#!/usr/bin/env python
# generated by minescan.py from mcpipy.com

import mcpi.minecraft as minecraft
import mcpi.block as block
import server

mc = minecraft.Minecraft.create(server.address)
mc.postToChat("Re-creating world")

# The following was generated by minescan.py from mcpipy.com
mc.setBlock(0,0,0,block.STONE_BRICK.id)
mc.setBlock(0,0,1,block.STONE_BRICK.id)
mc.setBlock(0,0,2,block.STONE_BRICK.id)
mc.setBlock(0,0,3,block.STONE_BRICK.id)
# Note this block is not supported in Minecraft Pi Edition v0.1.1
mc.setBlock(0,0,4,109)
# Note this block is not supported in Minecraft Pi Edition v0.1.1
mc.setBlock(0,0,5,109)
# Note this block is not supported in Minecraft Pi Edition v0.1.1
mc.setBlock(0,0,6,109)
mc.setBlock(0,0,7,block.STONE_BRICK.id)
mc.setBlock(0,0,8,block.STONE_BRICK.id)
mc.setBlock(0,0,9,block.STONE_BRICK.id)
mc.setBlock(0,0,10,block.STONE_BRICK.id)
mc.setBlock(1,0,0,block.STONE_BRICK.id)
mc.setBlock(1,0,1,block.STONE_BRICK.id)
mc.setBlock(1,0,2,block.STONE_BRICK.id)
mc.setBlock(1,0,3,block.DIRT.id)
mc.setBlock(1,0,4,block.GRAVEL.id)
mc.setBlock(1,0,5,block.GRAVEL.id)
mc.setBlock(1,0,6,block.GRAVEL.id)
mc.setBlock(1,0,7,block.DIRT.id)
mc.setBlock(1,0,8,block.STONE_BRICK.id)
mc.setBlock(1,0,9,block.STONE_BRICK.id)
mc.setBlock(1,0,10,block.STONE_BRICK.id)
mc.setBlock(2,0,0,block.STONE_BRICK.id)
mc.setBlock(2,0,1,block.STONE_BRICK.id)
mc.setBlock(2,0,2,block.STONE_BRICK.id)
mc.setBlock(2,0,3,block.DIRT.id)
mc.setBlock(2,0,4,block.GRAVEL.id)
mc.setBlock(2,0,5,block.GRAVEL.id)
mc.setBlock(2,0,6,block.GRAVEL.id)
mc.setBlock(2,0,7,block.DIRT.id)
mc.setBlock(2,0,8,block.STONE_BRICK.id)
mc.setBlock(2,0,9,block.STONE_BRICK.id)
mc.setBlock(2,0,10,block.STONE_BRICK.id)
mc.setBlock(3,0,0,block.STONE_BRICK.id)
mc.setBlock(3,0,1,block.STONE_BRICK.id)
mc.setBlock(3,0,2,block.FENCE.id)
mc.setBlock(3,0,3,block.STONE_BRICK.id)
mc.setBlock(3,0,4,block.STONE_BRICK.id)
mc.setBlock(3,0,5,block.WOOD_PLANKS.id)
mc.setBlock(3,0,6,block.STONE_BRICK.id)
mc.setBlock(3,0,7,block.STONE_BRICK.id)
mc.setBlock(3,0,8,block.FENCE.id)
mc.setBlock(3,0,9,block.STONE_BRICK.id)
mc.setBlock(3,0,10,block.STONE_BRICK.id)
mc.setBlock(4,0,0,block.STONE_BRICK.id)
mc.setBlock(4,0,1,block.STONE_BRICK.id)
mc.setBlock(4,0,2,block.STONE_BRICK.id)
mc.setBlock(4,0,3,block.STONE_BRICK.id)
mc.setBlock(4,0,4,block.WOOD_PLANKS.id)
mc.setBlock(4,0,5,block.WOOD_PLANKS.id)
mc.setBlock(4,0,6,block.WOOD_PLANKS.id)
mc.setBlock(4,0,7,block.STONE_BRICK.id)
mc.setBlock(4,0,8,block.STONE_BRICK.id)
mc.setBlock(4,0,9,block.STONE_BRICK.id)
mc.setBlock(4,0,10,block.STONE_BRICK.id)
mc.setBlock(5,0,0,block.STONE_BRICK.id)
mc.setBlock(5,0,1,block.STONE_BRICK.id)
mc.setBlock(5,0,2,block.STONE_BRICK.id)
mc.setBlock(5,0,3,block.STONE_BRICK.id)
mc.setBlock(5,0,4,block.WOOD_PLANKS.id)
mc.setBlock(5,0,5,block.GLOWSTONE_BLOCK.id)
mc.setBlock(5,0,6,block.WOOD_PLANKS.id)
mc.setBlock(5,0,7,block.STONE_BRICK.id)
mc.setBlock(5,0,8,block.STONE_BRICK.id)
mc.setBlock(5,0,9,block.STONE_BRICK.id)
mc.setBlock(5,0,10,block.STONE_BRICK.id)
mc.setBlock(6,0,0,block.STONE_BRICK.id)
mc.setBlock(6,0,1,block.STONE_BRICK.id)
mc.setBlock(6,0,2,block.STONE_BRICK.id)
mc.setBlock(6,0,3,block.STONE_BRICK.id)
mc.setBlock(6,0,4,block.WOOD_PLANKS.id)
mc.setBlock(6,0,5,block.WOOD_PLANKS.id)
mc.setBlock(6,0,6,block.WOOD_PLANKS.id)
mc.setBlock(6,0,7,block.STONE_BRICK.id)
mc.setBlock(6,0,8,block.STONE_BRICK.id)
mc.setBlock(6,0,9,block.STONE_BRICK.id)
mc.setBlock(6,0,10,block.STONE_BRICK.id)
mc.setBlock(7,0,0,block.STONE_BRICK.id)
mc.setBlock(7,0,1,block.STONE_BRICK.id)
mc.setBlock(7,0,2,block.FENCE.id)
mc.setBlock(7,0,3,block.STONE_BRICK.id)
mc.setBlock(7,0,4,block.STONE_BRICK.id)
mc.setBlock(7,0,5,block.STONE_BRICK.id)
mc.setBlock(7,0,6,block.STONE_BRICK.id)
mc.setBlock(7,0,7,block.STONE_BRICK.id)
mc.setBlock(7,0,8,block.FENCE.id)
mc.setBlock(7,0,9,block.STONE_BRICK.id)
mc.setBlock(7,0,10,block.STONE_BRICK.id)
mc.setBlock(8,0,0,block.STONE_BRICK.id)
mc.setBlock(8,0,1,block.STONE_BRICK.id)
mc.setBlock(8,0,2,block.STONE_BRICK.id)
mc.setBlock(8,0,3,block.FENCE.id)
mc.setBlock(8,0,4,block.STONE_BRICK.id)
mc.setBlock(8,0,5,block.STONE_BRICK.id)
mc.setBlock(8,0,6,block.STONE_BRICK.id)
mc.setBlock(8,0,7,block.STONE_BRICK.id)
mc.setBlock(8,0,8,block.STONE_BRICK.id)
mc.setBlock(8,0,9,block.STONE_BRICK.id)
mc.setBlock(8,0,10,block.STONE_BRICK.id)
mc.setBlock(9,0,0,block.STONE_BRICK.id)
mc.setBlock(9,0,1,block.STONE_BRICK.id)
mc.setBlock(9,0,2,block.STONE_BRICK.id)
mc.setBlock(9,0,3,block.STONE_BRICK.id)
mc.setBlock(9,0,4,block.STONE_BRICK.id)
mc.setBlock(9,0,5,block.STONE_BRICK.id)
mc.setBlock(9,0,6,block.STONE_BRICK.id)
mc.setBlock(9,0,7,block.STONE_BRICK.id)
mc.setBlock(9,0,8,block.STONE_BRICK.id)
mc.setBlock(9,0,9,block.STONE_BRICK.id)
mc.setBlock(9,0,10,block.STONE_BRICK.id)
mc.setBlock(10,0,0,block.STONE_BRICK.id)
mc.setBlock(10,0,1,block.STONE_BRICK.id)
mc.setBlock(10,0,2,block.STONE_BRICK.id)
mc.setBlock(10,0,3,block.STONE_BRICK.id)
mc.setBlock(10,0,4,block.STONE_BRICK.id)
mc.setBlock(10,0,5,block.STONE_BRICK.id)
mc.setBlock(10,0,6,block.STONE_BRICK.id)
mc.setBlock(10,0,7,block.STONE_BRICK.id)
mc.setBlock(10,0,8,block.STONE_BRICK.id)
mc.setBlock(10,0,9,block.STONE_BRICK.id)
mc.setBlock(10,0,10,block.STONE_BRICK.id)
mc.setBlock(0,1,0,block.FENCE.id)
mc.setBlock(0,1,1,block.LEAVES.id,13)
mc.setBlock(0,1,2,block.FENCE.id)
mc.setBlock(0,1,3,block.LEAVES.id,13)
mc.setBlock(0,1,7,block.LEAVES.id,13)
mc.setBlock(0,1,8,block.FENCE.id)
mc.setBlock(0,1,9,block.LEAVES.id,13)
mc.setBlock(0,1,10,block.FENCE.id)
mc.setBlock(1,1,0,block.LEAVES.id,13)
mc.setBlock(1,1,3,block.FLOWER_CYAN.id)
mc.setBlock(1,1,7,block.FLOWER_CYAN.id)
mc.setBlock(1,1,10,block.LEAVES.id,13)
mc.setBlock(2,1,0,block.FENCE.id)
mc.setBlock(2,1,3,block.FLOWER_YELLOW.id)
mc.setBlock(2,1,7,block.FLOWER_YELLOW.id)
mc.setBlock(2,1,10,block.FENCE.id)
mc.setBlock(3,1,0,block.LEAVES.id,13)
mc.setBlock(3,1,2,block.FENCE.id)
mc.setBlock(3,1,3,block.WOOD.id)
mc.setBlock(3,1,4,block.WOOD.id)
mc.setBlock(3,1,5,block.DOOR_WOOD.id)
mc.setBlock(3,1,6,block.WOOD.id)
mc.setBlock(3,1,7,block.WOOD.id)
mc.setBlock(3,1,8,block.FENCE.id)
mc.setBlock(3,1,10,block.LEAVES.id,13)
mc.setBlock(4,1,0,block.FENCE.id)
mc.setBlock(4,1,3,block.WOOD_PLANKS.id)
mc.setBlock(4,1,4,block.BED.id,3)
mc.setBlock(4,1,6,block.CRAFTING_TABLE.id)
mc.setBlock(4,1,7,block.WOOD_PLANKS.id)
mc.setBlock(4,1,10,block.FENCE.id)
mc.setBlock(5,1,0,block.LEAVES.id,13)
mc.setBlock(5,1,3,block.WOOD_PLANKS.id)
mc.setBlock(5,1,4,block.BED.id,11)
mc.setBlock(5,1,6,block.FURNACE_INACTIVE.id,2)
mc.setBlock(5,1,7,block.WOOD_PLANKS.id)
mc.setBlock(5,1,10,block.LEAVES.id,13)
mc.setBlock(6,1,0,block.FENCE.id)
mc.setBlock(6,1,3,block.WOOD_PLANKS.id)
mc.setBlock(6,1,4,block.BOOKSHELF.id)
mc.setBlock(6,1,5,block.CHEST.id,4)
# Note this block is not supported in Minecraft Pi Edition v0.1.1
mc.setBlock(6,1,6,245)
mc.setBlock(6,1,7,block.WOOD_PLANKS.id)
mc.setBlock(6,1,10,block.FENCE.id)
mc.setBlock(7,1,0,block.LEAVES.id,13)
mc.setBlock(7,1,2,block.FENCE.id)
mc.setBlock(7,1,3,block.WOOD.id)
mc.setBlock(7,1,4,block.WOOD_PLANKS.id)
mc.setBlock(7,1,5,block.WOOD_PLANKS.id)
mc.setBlock(7,1,6,block.WOOD_PLANKS.id)
mc.setBlock(7,1,7,block.WOOD.id)
mc.setBlock(7,1,8,block.FENCE.id)
mc.setBlock(7,1,10,block.LEAVES.id,13)
mc.setBlock(8,1,0,block.FENCE.id)
mc.setBlock(8,1,3,block.FENCE.id)
mc.setBlock(8,1,10,block.FENCE.id)
mc.setBlock(9,1,0,block.LEAVES.id,9)
mc.setBlock(9,1,10,block.LEAVES.id,13)
mc.setBlock(10,1,0,block.FENCE.id)
mc.setBlock(10,1,1,block.LEAVES.id,9)
mc.setBlock(10,1,2,block.FENCE.id)
mc.setBlock(10,1,3,block.LEAVES.id,9)
mc.setBlock(10,1,4,block.FENCE.id)
mc.setBlock(10,1,5,block.LEAVES.id,13)
mc.setBlock(10,1,6,block.FENCE.id)
mc.setBlock(10,1,7,block.LEAVES.id,13)
mc.setBlock(10,1,8,block.FENCE.id)
mc.setBlock(10,1,9,block.LEAVES.id,13)
mc.setBlock(10,1,10,block.FENCE.id)
mc.setBlock(0,2,0,block.LEAVES.id,13)
mc.setBlock(0,2,2,block.LEAVES.id,13)
mc.setBlock(0,2,8,block.LEAVES.id,13)
mc.setBlock(0,2,10,block.LEAVES.id,13)
mc.setBlock(2,2,0,block.LEAVES.id,13)
mc.setBlock(2,2,10,block.LEAVES.id,13)
mc.setBlock(3,2,3,block.WOOD.id)
mc.setBlock(3,2,4,block.GLASS.id)
mc.setBlock(3,2,5,block.DOOR_WOOD.id,8)
mc.setBlock(3,2,6,block.GLASS.id)
mc.setBlock(3,2,7,block.WOOD.id)
mc.setBlock(4,2,0,block.LEAVES.id,13)
mc.setBlock(4,2,3,block.WOOD_PLANKS.id)
# Note this block is not supported in Minecraft Pi Edition v0.1.1
mc.setBlock(4,2,4,96,5)
mc.setBlock(4,2,7,block.WOOD_PLANKS.id)
mc.setBlock(4,2,10,block.LEAVES.id,13)
mc.setBlock(5,2,3,block.GLASS_PANE.id)
mc.setBlock(5,2,7,block.GLASS_PANE.id)
mc.setBlock(6,2,0,block.LEAVES.id,13)
mc.setBlock(6,2,3,block.WOOD_PLANKS.id)
mc.setBlock(6,2,4,block.BOOKSHELF.id)
mc.setBlock(6,2,7,block.WOOD_PLANKS.id)
mc.setBlock(6,2,10,block.LEAVES.id,13)
mc.setBlock(7,2,3,block.WOOD.id)
mc.setBlock(7,2,4,block.WOOD_PLANKS.id)
mc.setBlock(7,2,5,block.GLASS_PANE.id)
mc.setBlock(7,2,6,block.WOOD_PLANKS.id)
mc.setBlock(7,2,7,block.WOOD.id)
mc.setBlock(8,2,0,block.LEAVES.id,9)
mc.setBlock(8,2,10,block.LEAVES.id,13)
mc.setBlock(10,2,0,block.LEAVES.id,9)
mc.setBlock(10,2,2,block.LEAVES.id,9)
mc.setBlock(10,2,4,block.LEAVES.id,13)
mc.setBlock(10,2,6,block.LEAVES.id,13)
mc.setBlock(10,2,8,block.LEAVES.id,13)
mc.setBlock(10,2,10,block.LEAVES.id,13)
mc.setBlock(0,3,0,block.LEAVES.id,13)
mc.setBlock(0,3,2,block.LEAVES.id,13)
mc.setBlock(0,3,8,block.LEAVES.id,13)
mc.setBlock(0,3,10,block.LEAVES.id,13)
mc.setBlock(2,3,0,block.LEAVES.id,13)
mc.setBlock(2,3,10,block.LEAVES.id,13)
mc.setBlock(3,3,3,block.WOOD.id)
mc.setBlock(3,3,4,block.WOOD_PLANKS.id)
mc.setBlock(3,3,5,block.WOOD_PLANKS.id)
mc.setBlock(3,3,6,block.WOOD_PLANKS.id)
mc.setBlock(3,3,7,block.WOOD.id)
mc.setBlock(4,3,0,block.LEAVES.id,13)
mc.setBlock(4,3,3,block.WOOD_PLANKS.id)
mc.setBlock(4,3,7,block.WOOD_PLANKS.id)
mc.setBlock(4,3,10,block.LEAVES.id,13)
mc.setBlock(5,3,3,block.WOOD_PLANKS.id)
mc.setBlock(5,3,7,block.WOOD_PLANKS.id)
mc.setBlock(6,3,0,block.LEAVES.id,13)
mc.setBlock(6,3,3,block.WOOD_PLANKS.id)
mc.setBlock(6,3,7,block.WOOD_PLANKS.id)
mc.setBlock(6,3,10,block.LEAVES.id,13)
mc.setBlock(7,3,3,block.WOOD.id)
mc.setBlock(7,3,4,block.WOOD_PLANKS.id)
mc.setBlock(7,3,5,block.WOOD_PLANKS.id)
mc.setBlock(7,3,6,block.WOOD_PLANKS.id)
mc.setBlock(7,3,7,block.WOOD.id)
mc.setBlock(8,3,0,block.LEAVES.id,9)
mc.setBlock(8,3,10,block.LEAVES.id,13)
mc.setBlock(10,3,0,block.LEAVES.id,9)
mc.setBlock(10,3,2,block.LEAVES.id,9)
mc.setBlock(10,3,4,block.LEAVES.id,13)
mc.setBlock(10,3,6,block.LEAVES.id,13)
mc.setBlock(10,3,8,block.LEAVES.id,13)
mc.setBlock(10,3,10,block.LEAVES.id,13)
mc.setBlock(0,4,0,block.FENCE.id)
mc.setBlock(0,4,10,block.FENCE.id)
mc.setBlock(3,4,3,block.STONE_SLAB.id,2)
mc.setBlock(3,4,4,block.STAIRS_WOOD.id)
mc.setBlock(3,4,5,block.STAIRS_WOOD.id)
mc.setBlock(3,4,6,block.STAIRS_WOOD.id)
mc.setBlock(3,4,7,block.STONE_SLAB.id,2)
mc.setBlock(4,4,0,block.FENCE.id)
mc.setBlock(4,4,3,block.STAIRS_WOOD.id,2)
mc.setBlock(4,4,4,block.GLASS.id)
mc.setBlock(4,4,5,block.GLASS.id)
mc.setBlock(4,4,6,block.GLASS.id)
mc.setBlock(4,4,7,block.STAIRS_WOOD.id,3)
mc.setBlock(4,4,10,block.FENCE.id)
mc.setBlock(5,4,3,block.STAIRS_WOOD.id,2)
mc.setBlock(5,4,4,block.GLASS.id)
mc.setBlock(5,4,5,block.GLASS.id)
mc.setBlock(5,4,6,block.GLASS.id)
mc.setBlock(5,4,7,block.STAIRS_WOOD.id,3)
mc.setBlock(6,4,0,block.FENCE.id)
mc.setBlock(6,4,3,block.STAIRS_WOOD.id,2)
mc.setBlock(6,4,4,block.GLASS.id)
mc.setBlock(6,4,5,block.GLASS.id)
mc.setBlock(6,4,6,block.GLASS.id)
mc.setBlock(6,4,7,block.STAIRS_WOOD.id,3)
mc.setBlock(6,4,10,block.FENCE.id)
mc.setBlock(7,4,3,block.STONE_SLAB.id,2)
mc.setBlock(7,4,4,block.STAIRS_WOOD.id,1)
mc.setBlock(7,4,5,block.STAIRS_WOOD.id,1)
mc.setBlock(7,4,6,block.STAIRS_WOOD.id,1)
mc.setBlock(7,4,7,block.STONE_SLAB.id,2)
mc.setBlock(10,4,0,block.FENCE.id)
mc.setBlock(10,4,4,block.FENCE.id)
mc.setBlock(10,4,6,block.FENCE.id)
mc.setBlock(10,4,10,block.FENCE.id)
mc.setBlock(0,5,0,block.GLOWSTONE_BLOCK.id)
mc.setBlock(0,5,10,block.GLOWSTONE_BLOCK.id)
mc.setBlock(4,5,0,block.GLOWSTONE_BLOCK.id)
mc.setBlock(4,5,10,block.GLOWSTONE_BLOCK.id)
mc.setBlock(6,5,0,block.GLOWSTONE_BLOCK.id)
mc.setBlock(6,5,10,block.GLOWSTONE_BLOCK.id)
mc.setBlock(10,5,0,block.GLOWSTONE_BLOCK.id)
mc.setBlock(10,5,4,block.GLOWSTONE_BLOCK.id)
mc.setBlock(10,5,6,block.GLOWSTONE_BLOCK.id)
mc.setBlock(10,5,10,block.GLOWSTONE_BLOCK.id)
mc.postToChat('World Re-created!')
